2016-11-16 13:38:13,193 [WARNING] django.request: Not Found: /
2016-11-16 13:38:13,419 [WARNING] django.request: Not Found: /favicon.ico
2016-11-16 13:38:13,486 [WARNING] django.request: Not Found: /favicon.ico
2016-11-16 13:54:57,941 [DEBUG] django.request: <WSGIRequest: POST '/create_customer'>
2016-11-16 13:54:58,188 [ERROR] django.request: Internal Server Error: /login
Traceback (most recent call last):
  File "/Library/Python/2.7/site-packages/django/core/handlers/base.py", line 131, in get_response
    response = middleware_method(request, response)
  File "/Library/Python/2.7/site-packages/django/middleware/clickjacking.py", line 32, in process_response
    if response.get('X-Frame-Options') is not None:
TypeError: unbound method get() must be called with HttpResponseBadRequest instance as first argument (got str instance instead)
2016-11-16 13:54:58,434 [ERROR] django.request: Internal Server Error: /finish_trip
Traceback (most recent call last):
  File "/Library/Python/2.7/site-packages/django/core/handlers/exception.py", line 39, in inner
    response = get_response(request)
  File "/Library/Python/2.7/site-packages/django/core/handlers/base.py", line 249, in _legacy_get_response
    response = self._get_response(request)
  File "/Library/Python/2.7/site-packages/django/core/handlers/base.py", line 187, in _get_response
    response = self.process_exception_by_middleware(e, request)
  File "/Library/Python/2.7/site-packages/django/core/handlers/base.py", line 185, in _get_response
    response = wrapped_callback(request, *callback_args, **callback_kwargs)
  File "/Library/Python/2.7/site-packages/django/views/generic/base.py", line 68, in view
    return self.dispatch(request, *args, **kwargs)
  File "/Library/Python/2.7/site-packages/django/views/generic/base.py", line 88, in dispatch
    return handler(request, *args, **kwargs)
  File "/Users/tormodfladby/Documents/TorgeirsArbeid/GOtuk/trip/views.py", line 264, in post
    return self.finish_trip(request)
  File "/Users/tormodfladby/Documents/TorgeirsArbeid/GOtuk/trip/views.py", line 68, in finish_trip
    dd = DriverDetails.objects.get(user_instance=request.user)
  File "/Library/Python/2.7/site-packages/django/db/models/manager.py", line 85, in manager_method
    return getattr(self.get_queryset(), name)(*args, **kwargs)
  File "/Library/Python/2.7/site-packages/django/db/models/query.py", line 376, in get
    clone = self.filter(*args, **kwargs)
  File "/Library/Python/2.7/site-packages/django/db/models/query.py", line 796, in filter
    return self._filter_or_exclude(False, *args, **kwargs)
  File "/Library/Python/2.7/site-packages/django/db/models/query.py", line 814, in _filter_or_exclude
    clone.query.add_q(Q(*args, **kwargs))
  File "/Library/Python/2.7/site-packages/django/db/models/sql/query.py", line 1227, in add_q
    clause, _ = self._add_q(q_object, self.used_aliases)
  File "/Library/Python/2.7/site-packages/django/db/models/sql/query.py", line 1253, in _add_q
    allow_joins=allow_joins, split_subq=split_subq,
  File "/Library/Python/2.7/site-packages/django/db/models/sql/query.py", line 1158, in build_filter
    self.check_related_objects(field, value, opts)
  File "/Library/Python/2.7/site-packages/django/db/models/sql/query.py", line 1057, in check_related_objects
    for v in value:
  File "/Library/Python/2.7/site-packages/django/utils/functional.py", line 235, in inner
    return func(self._wrapped, *args)
TypeError: 'AnonymousUser' object is not iterable
2016-11-16 14:06:12,340 [DEBUG] django.request: <WSGIRequest: POST '/create_customer'>
2016-11-16 14:06:13,100 [ERROR] django.request: Internal Server Error: /finish_trip
Traceback (most recent call last):
  File "/Library/Python/2.7/site-packages/django/core/handlers/exception.py", line 39, in inner
    response = get_response(request)
  File "/Library/Python/2.7/site-packages/django/core/handlers/base.py", line 249, in _legacy_get_response
    response = self._get_response(request)
  File "/Library/Python/2.7/site-packages/django/core/handlers/base.py", line 187, in _get_response
    response = self.process_exception_by_middleware(e, request)
  File "/Library/Python/2.7/site-packages/django/core/handlers/base.py", line 185, in _get_response
    response = wrapped_callback(request, *callback_args, **callback_kwargs)
  File "/Library/Python/2.7/site-packages/django/views/generic/base.py", line 68, in view
    return self.dispatch(request, *args, **kwargs)
  File "/Library/Python/2.7/site-packages/django/views/generic/base.py", line 88, in dispatch
    return handler(request, *args, **kwargs)
  File "/Users/tormodfladby/Documents/TorgeirsArbeid/GOtuk/trip/views.py", line 264, in post
    return self.finish_trip(request)
  File "/Users/tormodfladby/Documents/TorgeirsArbeid/GOtuk/trip/views.py", line 69, in finish_trip
    debt_instance = DebtTable.objects.get(driver=dd)
  File "/Library/Python/2.7/site-packages/django/db/models/manager.py", line 85, in manager_method
    return getattr(self.get_queryset(), name)(*args, **kwargs)
  File "/Library/Python/2.7/site-packages/django/db/models/query.py", line 385, in get
    self.model._meta.object_name
DoesNotExist: DebtTable matching query does not exist.
2016-11-16 14:13:38,428 [ERROR] django.request: Internal Server Error: /admin/users/customuser/add/
Traceback (most recent call last):
  File "/Library/Python/2.7/site-packages/django/core/handlers/exception.py", line 39, in inner
    response = get_response(request)
  File "/Library/Python/2.7/site-packages/django/core/handlers/base.py", line 249, in _legacy_get_response
    response = self._get_response(request)
  File "/Library/Python/2.7/site-packages/django/core/handlers/base.py", line 187, in _get_response
    response = self.process_exception_by_middleware(e, request)
  File "/Library/Python/2.7/site-packages/django/core/handlers/base.py", line 185, in _get_response
    response = wrapped_callback(request, *callback_args, **callback_kwargs)
  File "/Library/Python/2.7/site-packages/django/contrib/admin/options.py", line 544, in wrapper
    return self.admin_site.admin_view(view)(*args, **kwargs)
  File "/Library/Python/2.7/site-packages/django/utils/decorators.py", line 149, in _wrapped_view
    response = view_func(request, *args, **kwargs)
  File "/Library/Python/2.7/site-packages/django/views/decorators/cache.py", line 57, in _wrapped_view_func
    response = view_func(request, *args, **kwargs)
  File "/Library/Python/2.7/site-packages/django/contrib/admin/sites.py", line 211, in inner
    return view(request, *args, **kwargs)
  File "/Library/Python/2.7/site-packages/django/utils/decorators.py", line 67, in _wrapper
    return bound_func(*args, **kwargs)
  File "/Library/Python/2.7/site-packages/django/views/decorators/debug.py", line 76, in sensitive_post_parameters_wrapper
    return view(request, *args, **kwargs)
  File "/Library/Python/2.7/site-packages/django/utils/decorators.py", line 63, in bound_func
    return func.__get__(self, type(self))(*args2, **kwargs2)
  File "/Library/Python/2.7/site-packages/django/utils/decorators.py", line 67, in _wrapper
    return bound_func(*args, **kwargs)
  File "/Library/Python/2.7/site-packages/django/utils/decorators.py", line 149, in _wrapped_view
    response = view_func(request, *args, **kwargs)
  File "/Library/Python/2.7/site-packages/django/utils/decorators.py", line 63, in bound_func
    return func.__get__(self, type(self))(*args2, **kwargs2)
  File "/Library/Python/2.7/site-packages/django/utils/decorators.py", line 185, in inner
    return func(*args, **kwargs)
  File "/Library/Python/2.7/site-packages/django/contrib/auth/admin.py", line 128, in add_view
    extra_context)
  File "/Library/Python/2.7/site-packages/django/contrib/admin/options.py", line 1509, in add_view
    return self.changeform_view(request, None, form_url, extra_context)
  File "/Library/Python/2.7/site-packages/django/utils/decorators.py", line 67, in _wrapper
    return bound_func(*args, **kwargs)
  File "/Library/Python/2.7/site-packages/django/utils/decorators.py", line 149, in _wrapped_view
    response = view_func(request, *args, **kwargs)
  File "/Library/Python/2.7/site-packages/django/utils/decorators.py", line 63, in bound_func
    return func.__get__(self, type(self))(*args2, **kwargs2)
  File "/Library/Python/2.7/site-packages/django/utils/decorators.py", line 185, in inner
    return func(*args, **kwargs)
  File "/Library/Python/2.7/site-packages/django/contrib/admin/options.py", line 1450, in changeform_view
    self.save_related(request, form, formsets, not add)
  File "/Library/Python/2.7/site-packages/django/contrib/admin/options.py", line 1031, in save_related
    self.save_formset(request, form, formset, change=change)
  File "/Library/Python/2.7/site-packages/django/contrib/admin/options.py", line 1019, in save_formset
    formset.save()
  File "/Library/Python/2.7/site-packages/django/forms/models.py", line 651, in save
    return self.save_existing_objects(commit) + self.save_new_objects(commit)
  File "/Library/Python/2.7/site-packages/django/forms/models.py", line 784, in save_new_objects
    self.new_objects.append(self.save_new(form, commit=commit))
  File "/Library/Python/2.7/site-packages/django/forms/models.py", line 924, in save_new
    obj = form.save(commit=False)
  File "/Users/tormodfladby/Documents/TorgeirsArbeid/GOtuk/users/forms/register.py", line 125, in save
    user = details.user_istance
AttributeError: 'DriverDetails' object has no attribute 'user_istance'
2016-11-16 14:13:52,610 [ERROR] django.request: Internal Server Error: /admin/users/customuser/add/
Traceback (most recent call last):
  File "/Library/Python/2.7/site-packages/django/core/handlers/exception.py", line 39, in inner
    response = get_response(request)
  File "/Library/Python/2.7/site-packages/django/core/handlers/base.py", line 249, in _legacy_get_response
    response = self._get_response(request)
  File "/Library/Python/2.7/site-packages/django/core/handlers/base.py", line 187, in _get_response
    response = self.process_exception_by_middleware(e, request)
  File "/Library/Python/2.7/site-packages/django/core/handlers/base.py", line 185, in _get_response
    response = wrapped_callback(request, *callback_args, **callback_kwargs)
  File "/Library/Python/2.7/site-packages/django/contrib/admin/options.py", line 544, in wrapper
    return self.admin_site.admin_view(view)(*args, **kwargs)
  File "/Library/Python/2.7/site-packages/django/utils/decorators.py", line 149, in _wrapped_view
    response = view_func(request, *args, **kwargs)
  File "/Library/Python/2.7/site-packages/django/views/decorators/cache.py", line 57, in _wrapped_view_func
    response = view_func(request, *args, **kwargs)
  File "/Library/Python/2.7/site-packages/django/contrib/admin/sites.py", line 211, in inner
    return view(request, *args, **kwargs)
  File "/Library/Python/2.7/site-packages/django/utils/decorators.py", line 67, in _wrapper
    return bound_func(*args, **kwargs)
  File "/Library/Python/2.7/site-packages/django/views/decorators/debug.py", line 76, in sensitive_post_parameters_wrapper
    return view(request, *args, **kwargs)
  File "/Library/Python/2.7/site-packages/django/utils/decorators.py", line 63, in bound_func
    return func.__get__(self, type(self))(*args2, **kwargs2)
  File "/Library/Python/2.7/site-packages/django/utils/decorators.py", line 67, in _wrapper
    return bound_func(*args, **kwargs)
  File "/Library/Python/2.7/site-packages/django/utils/decorators.py", line 149, in _wrapped_view
    response = view_func(request, *args, **kwargs)
  File "/Library/Python/2.7/site-packages/django/utils/decorators.py", line 63, in bound_func
    return func.__get__(self, type(self))(*args2, **kwargs2)
  File "/Library/Python/2.7/site-packages/django/utils/decorators.py", line 185, in inner
    return func(*args, **kwargs)
  File "/Library/Python/2.7/site-packages/django/contrib/auth/admin.py", line 128, in add_view
    extra_context)
  File "/Library/Python/2.7/site-packages/django/contrib/admin/options.py", line 1509, in add_view
    return self.changeform_view(request, None, form_url, extra_context)
  File "/Library/Python/2.7/site-packages/django/utils/decorators.py", line 67, in _wrapper
    return bound_func(*args, **kwargs)
  File "/Library/Python/2.7/site-packages/django/utils/decorators.py", line 149, in _wrapped_view
    response = view_func(request, *args, **kwargs)
  File "/Library/Python/2.7/site-packages/django/utils/decorators.py", line 63, in bound_func
    return func.__get__(self, type(self))(*args2, **kwargs2)
  File "/Library/Python/2.7/site-packages/django/utils/decorators.py", line 185, in inner
    return func(*args, **kwargs)
  File "/Library/Python/2.7/site-packages/django/contrib/admin/options.py", line 1450, in changeform_view
    self.save_related(request, form, formsets, not add)
  File "/Library/Python/2.7/site-packages/django/contrib/admin/options.py", line 1031, in save_related
    self.save_formset(request, form, formset, change=change)
  File "/Library/Python/2.7/site-packages/django/contrib/admin/options.py", line 1019, in save_formset
    formset.save()
  File "/Library/Python/2.7/site-packages/django/forms/models.py", line 651, in save
    return self.save_existing_objects(commit) + self.save_new_objects(commit)
  File "/Library/Python/2.7/site-packages/django/forms/models.py", line 784, in save_new_objects
    self.new_objects.append(self.save_new(form, commit=commit))
  File "/Library/Python/2.7/site-packages/django/forms/models.py", line 924, in save_new
    obj = form.save(commit=False)
  File "/Users/tormodfladby/Documents/TorgeirsArbeid/GOtuk/users/forms/register.py", line 127, in save
    debt = DebtTable(driver = dd, debt = 0.0, driver_email=user.email, driver_name=driver_name)
NameError: global name 'dd' is not defined
2016-11-16 14:14:37,166 [DEBUG] django.request: <WSGIRequest: POST '/create_customer'>
2016-11-16 14:14:37,817 [ERROR] django.request: Internal Server Error: /finish_trip
Traceback (most recent call last):
  File "/Library/Python/2.7/site-packages/django/core/handlers/exception.py", line 39, in inner
    response = get_response(request)
  File "/Library/Python/2.7/site-packages/django/core/handlers/base.py", line 249, in _legacy_get_response
    response = self._get_response(request)
  File "/Library/Python/2.7/site-packages/django/core/handlers/base.py", line 187, in _get_response
    response = self.process_exception_by_middleware(e, request)
  File "/Library/Python/2.7/site-packages/django/core/handlers/base.py", line 185, in _get_response
    response = wrapped_callback(request, *callback_args, **callback_kwargs)
  File "/Library/Python/2.7/site-packages/django/views/generic/base.py", line 68, in view
    return self.dispatch(request, *args, **kwargs)
  File "/Library/Python/2.7/site-packages/django/views/generic/base.py", line 88, in dispatch
    return handler(request, *args, **kwargs)
  File "/Users/tormodfladby/Documents/TorgeirsArbeid/GOtuk/trip/views.py", line 264, in post
    return self.finish_trip(request)
  File "/Users/tormodfladby/Documents/TorgeirsArbeid/GOtuk/trip/views.py", line 69, in finish_trip
    debt_instance = DebtTable.objects.get(driver=dd)
  File "/Library/Python/2.7/site-packages/django/db/models/manager.py", line 85, in manager_method
    return getattr(self.get_queryset(), name)(*args, **kwargs)
  File "/Library/Python/2.7/site-packages/django/db/models/query.py", line 385, in get
    self.model._meta.object_name
DoesNotExist: DebtTable matching query does not exist.
2016-11-16 14:16:17,491 [DEBUG] django.request: <WSGIRequest: POST '/create_customer'>
2016-11-16 14:16:18,136 [ERROR] django.request: Internal Server Error: /finish_trip
Traceback (most recent call last):
  File "/Library/Python/2.7/site-packages/django/core/handlers/exception.py", line 39, in inner
    response = get_response(request)
  File "/Library/Python/2.7/site-packages/django/core/handlers/base.py", line 249, in _legacy_get_response
    response = self._get_response(request)
  File "/Library/Python/2.7/site-packages/django/core/handlers/base.py", line 187, in _get_response
    response = self.process_exception_by_middleware(e, request)
  File "/Library/Python/2.7/site-packages/django/core/handlers/base.py", line 185, in _get_response
    response = wrapped_callback(request, *callback_args, **callback_kwargs)
  File "/Library/Python/2.7/site-packages/django/views/generic/base.py", line 68, in view
    return self.dispatch(request, *args, **kwargs)
  File "/Library/Python/2.7/site-packages/django/views/generic/base.py", line 88, in dispatch
    return handler(request, *args, **kwargs)
  File "/Users/tormodfladby/Documents/TorgeirsArbeid/GOtuk/trip/views.py", line 264, in post
    return self.finish_trip(request)
  File "/Users/tormodfladby/Documents/TorgeirsArbeid/GOtuk/trip/views.py", line 69, in finish_trip
    debt_instance = DebtTable.objects.get(driver=dd)
  File "/Library/Python/2.7/site-packages/django/db/models/manager.py", line 85, in manager_method
    return getattr(self.get_queryset(), name)(*args, **kwargs)
  File "/Library/Python/2.7/site-packages/django/db/models/query.py", line 385, in get
    self.model._meta.object_name
DoesNotExist: DebtTable matching query does not exist.
2016-11-16 14:41:42,725 [ERROR] django.request: Internal Server Error: /admin/users/customuser/add/
Traceback (most recent call last):
  File "/Library/Python/2.7/site-packages/django/core/handlers/exception.py", line 39, in inner
    response = get_response(request)
  File "/Library/Python/2.7/site-packages/django/core/handlers/base.py", line 249, in _legacy_get_response
    response = self._get_response(request)
  File "/Library/Python/2.7/site-packages/django/core/handlers/base.py", line 187, in _get_response
    response = self.process_exception_by_middleware(e, request)
  File "/Library/Python/2.7/site-packages/django/core/handlers/base.py", line 185, in _get_response
    response = wrapped_callback(request, *callback_args, **callback_kwargs)
  File "/Library/Python/2.7/site-packages/django/contrib/admin/options.py", line 544, in wrapper
    return self.admin_site.admin_view(view)(*args, **kwargs)
  File "/Library/Python/2.7/site-packages/django/utils/decorators.py", line 149, in _wrapped_view
    response = view_func(request, *args, **kwargs)
  File "/Library/Python/2.7/site-packages/django/views/decorators/cache.py", line 57, in _wrapped_view_func
    response = view_func(request, *args, **kwargs)
  File "/Library/Python/2.7/site-packages/django/contrib/admin/sites.py", line 211, in inner
    return view(request, *args, **kwargs)
  File "/Library/Python/2.7/site-packages/django/utils/decorators.py", line 67, in _wrapper
    return bound_func(*args, **kwargs)
  File "/Library/Python/2.7/site-packages/django/views/decorators/debug.py", line 76, in sensitive_post_parameters_wrapper
    return view(request, *args, **kwargs)
  File "/Library/Python/2.7/site-packages/django/utils/decorators.py", line 63, in bound_func
    return func.__get__(self, type(self))(*args2, **kwargs2)
  File "/Library/Python/2.7/site-packages/django/utils/decorators.py", line 67, in _wrapper
    return bound_func(*args, **kwargs)
  File "/Library/Python/2.7/site-packages/django/utils/decorators.py", line 149, in _wrapped_view
    response = view_func(request, *args, **kwargs)
  File "/Library/Python/2.7/site-packages/django/utils/decorators.py", line 63, in bound_func
    return func.__get__(self, type(self))(*args2, **kwargs2)
  File "/Library/Python/2.7/site-packages/django/utils/decorators.py", line 185, in inner
    return func(*args, **kwargs)
  File "/Library/Python/2.7/site-packages/django/contrib/auth/admin.py", line 128, in add_view
    extra_context)
  File "/Library/Python/2.7/site-packages/django/contrib/admin/options.py", line 1509, in add_view
    return self.changeform_view(request, None, form_url, extra_context)
  File "/Library/Python/2.7/site-packages/django/utils/decorators.py", line 67, in _wrapper
    return bound_func(*args, **kwargs)
  File "/Library/Python/2.7/site-packages/django/utils/decorators.py", line 149, in _wrapped_view
    response = view_func(request, *args, **kwargs)
  File "/Library/Python/2.7/site-packages/django/utils/decorators.py", line 63, in bound_func
    return func.__get__(self, type(self))(*args2, **kwargs2)
  File "/Library/Python/2.7/site-packages/django/utils/decorators.py", line 185, in inner
    return func(*args, **kwargs)
  File "/Library/Python/2.7/site-packages/django/contrib/admin/options.py", line 1464, in changeform_view
    formsets, inline_instances = self._create_formsets(request, form.instance, change=False)
  File "/Library/Python/2.7/site-packages/django/contrib/admin/options.py", line 1815, in _create_formsets
    formsets.append(FormSet(**formset_params))
  File "/Library/Python/2.7/site-packages/django/forms/models.py", line 568, in __init__
    super(BaseModelFormSet, self).__init__(**defaults)
TypeError: __init__() got an unexpected keyword argument 'instance'
2016-11-16 14:53:50,294 [ERROR] django.request: Internal Server Error: /admin/users/customuser/21/change/
Traceback (most recent call last):
  File "/Library/Python/2.7/site-packages/django/core/handlers/exception.py", line 39, in inner
    response = get_response(request)
  File "/Library/Python/2.7/site-packages/django/core/handlers/base.py", line 249, in _legacy_get_response
    response = self._get_response(request)
  File "/Library/Python/2.7/site-packages/django/core/handlers/base.py", line 187, in _get_response
    response = self.process_exception_by_middleware(e, request)
  File "/Library/Python/2.7/site-packages/django/core/handlers/base.py", line 185, in _get_response
    response = wrapped_callback(request, *callback_args, **callback_kwargs)
  File "/Library/Python/2.7/site-packages/django/contrib/admin/options.py", line 544, in wrapper
    return self.admin_site.admin_view(view)(*args, **kwargs)
  File "/Library/Python/2.7/site-packages/django/utils/decorators.py", line 149, in _wrapped_view
    response = view_func(request, *args, **kwargs)
  File "/Library/Python/2.7/site-packages/django/views/decorators/cache.py", line 57, in _wrapped_view_func
    response = view_func(request, *args, **kwargs)
  File "/Library/Python/2.7/site-packages/django/contrib/admin/sites.py", line 211, in inner
    return view(request, *args, **kwargs)
  File "/Library/Python/2.7/site-packages/django/contrib/admin/options.py", line 1512, in change_view
    return self.changeform_view(request, object_id, form_url, extra_context)
  File "/Library/Python/2.7/site-packages/django/utils/decorators.py", line 67, in _wrapper
    return bound_func(*args, **kwargs)
  File "/Library/Python/2.7/site-packages/django/utils/decorators.py", line 149, in _wrapped_view
    response = view_func(request, *args, **kwargs)
  File "/Library/Python/2.7/site-packages/django/utils/decorators.py", line 63, in bound_func
    return func.__get__(self, type(self))(*args2, **kwargs2)
  File "/Library/Python/2.7/site-packages/django/utils/decorators.py", line 185, in inner
    return func(*args, **kwargs)
  File "/Library/Python/2.7/site-packages/django/contrib/admin/options.py", line 1441, in changeform_view
    if form.is_valid():
  File "/Library/Python/2.7/site-packages/django/forms/forms.py", line 169, in is_valid
    return self.is_bound and not self.errors
  File "/Library/Python/2.7/site-packages/django/forms/forms.py", line 161, in errors
    self.full_clean()
  File "/Library/Python/2.7/site-packages/django/forms/forms.py", line 370, in full_clean
    self._clean_fields()
  File "/Library/Python/2.7/site-packages/django/forms/forms.py", line 391, in _clean_fields
    value = getattr(self, 'clean_%s' % name)()
  File "/Users/tormodfladby/Documents/TorgeirsArbeid/GOtuk/users/forms/register.py", line 90, in clean_password
    if password1 in self.cleaned_data['password1'] and password2 in self.cleaned_data['password2']:
KeyError: 'password1'
